<?xml version="1.0" ?>
<mujoco model="free_floating_spacecraft_manipulator">
    <compiler angle="radian" />
    <option timestep="0.2" iterations="30">
        <flag gravity="disable" />
    </option>
    <asset>
		<texture type="skybox" builtin="none" file="space.png" rgb1="1 1 1" rgb2=".6 .8 1" />
        <texture name="texplane" type="2d" builtin="checker" rgb1=".2 .3 .4" rgb2=".1 0.15 0.2" width="512" height="512"/>
        <material name="MatGnd" reflectance="0.5" texture="texplane" texrepeat="1 1" texuniform="true"/>

        <mesh name="hand_col" file="meshes/collision/hand.stl"/>
        <mesh name="finger_col" file="meshes/collision/finger.stl" scale='1.75 1.0 1.75'/>
        <mesh name="hand_viz" file="meshes/visual/hand.stl"/>
        <mesh name="finger_viz" file="meshes/collision/finger.stl" scale='1.75 1.0 1.75'/>
    </asset>
    <size njmax="1000" nconmax="100" />

<!--     <contact>       
        <exclude body1="right_upper_shoulder" body2="torso"/>
        <exclude body1="right_upper_shoulder" body2="right_upper_elbow"/>
        <exclude body1="right_lower_shoulder" body2="torso"/>

        <exclude body1="left_upper_shoulder" body2="torso"/>
        <exclude body1="left_upper_shoulder" body2="left_upper_elbow"/>
        <exclude body1="left_lower_shoulder" body2="torso"/>
        
        <exclude body1="collision_head_link_1" body2="torso"/>
        <exclude body1="collision_head_link_2" body2="torso"/>
        <exclude body1="r_gripper_r_finger" body2="r_gripper_l_finger"/>
        <exclude body1="l_gripper_r_finger" body2="l_gripper_l_finger"/>
    </contact>
 -->

    <default>
        <default class="panda">
            <joint pos="0 0 0" axis="0 0 1" limited="true"/>
            <position forcelimited="true" ctrllimited="true" user="1002 40 2001 -0.005 0.005"/>
            <default class="spaceRobot_viz">
                <geom contype="0" conaffinity="0" group="0" type="mesh" rgba=".95 .99 .92 1" mass="0"/>
            </default>

            <default class="spaceRobot_col">
                <geom contype="1" conaffinity="1" group="3" type="mesh" rgba=".5 .6 .7 1"/>
            </default>

             <default class="spaceRobot_finger">
                <joint damping="100" armature='5'/>
                <geom friction="1 0.5 0.0001" solref="0.01 1" solimp="0.8 0.9 0.001" margin="0.001" user="0" rgba="0.5 0.6 0.7 .4" contype="1" conaffinity="0" condim="6" group="3" />
                <position user="1002 40 2001 -0.0001 0.0001"/>
            </default>
        </default>

    </default>

    <worldbody>
        <light directional="false" diffuse=".8 .8 .8" specular="0.3 0.3 0.3" pos="1  1 3" dir="-1 -1 -3"/>
        <light directional="false" diffuse=".8 .8 .8" specular="0.3 0.3 0.3" pos="1 -1 3" dir="-1 1 -3"/>
        <light directional="false" diffuse=".8 .8 .8" specular="0.3 0.3 0.3" pos="-1 0 3" dir="1 0 -3" />
        <!-- <geom name="ground" pos="0 0 0" size="20 20 20" material="MatGnd" type="plane" contype="1" conaffinity="1"/> -->
<!--        <site name="debrisSite" pos="-0.5 0.5 7.0" rgba="0.2 0.6 0.2 0.25" size=".05" type="sphere" />-->
        <site name="debrisSite" pos="-2. 0. 5.5" rgba="0.2 0.6 0.2 0.25" size=".05" type="sphere" />
<!--        <body name="sdebris" pos="-2 3 5.5" >-->
<!--            <inertial mass="20" pos="0 0 0" diaginertia="14 14 20"/>-->
<!--            <joint name="freeDebrisJoint" type="free"/>-->
<!--            <geom size="0.05 0.05 0.15" type="box" rgba=".7 .4 0.6 0.9" />-->
<!--            <site name="debrisSite" pos="0 0 0" type="sphere" size="0.01" rgba="0.1 0.2 0.3 1" />-->
<!--        </body>-->
        <body name="spacecraft_base" pos="0 0 5" >
            <site name="baseSite" pos="0 0 0" type="sphere" size="0.01" rgba="0.1 0.2 0.3 1" />
<!--            <inertial mass="50000" pos="0 0 0" diaginertia="14000 14000 10400"/>-->
            <inertial mass="500" pos="0 0 0" diaginertia="1400 1400 1040"/>
            <joint name="BasefloatingJoint" type="free" damping="0"/>
<!--            <joint name="BasefloatingJoint" type="free" damping="1e+11"/>-->
            <geom size="1.05 1.05 1.05" type="box" rgba="1 1 0.6 1" />
            <body name="spacecraft_link1" pos="1.2268 1.2268 0" quat="0.653281 -0.653281 0.270598 -0.270598">
                <inertial pos="0 0 0" mass="20" diaginertia="0.1 0.1 0.1" />
                <joint damping="200" name="sjoint1" pos="0 0 0" axis="0 0 1" limited="true" range="-3.14159 3.14159" />
                <geom size="0.04 0.25" type="cylinder" rgba="0 0 0.8 1" />
                <body name="spacecraft_link2" pos="-0.3182 0 -0.0682" euler="0 -2.355 0">
                    <inertial pos="0 0 0" quat="0.5 0.5 0.5 0.5" mass="30" diaginertia="25 25 0.25" />
                    <joint damping="200" name="sjoint2" pos="0 0 -0.45" axis="0 1 0" limited="true" range="-3.14159 3.14159" />
                    <geom size="0.04 0.45" type="cylinder" rgba="0 0.5 0.8 1" />
                    <body name="spacecraft_link3" pos="0 0 0.90" euler="0 0 0">
                        <inertial pos="0 0 0" quat="0.5 0.5 0.5 0.5" mass="30" diaginertia="25 25 0.25" />
                        <joint damping="200" name="sjoint3" pos="0 0 -0.45" axis="1 0 0" limited="true" range="-3.14159 3.14159" />
                        <geom size="0.04 0.45" type="cylinder" rgba="0.5 0 0.8 1" />
                        <body name="spacecraft_link4" pos="0 0 0.85" euler="0 0 0">
                            <inertial pos="0 0 0" quat="0.5 0.5 0.5 0.5" mass="20" diaginertia="25 25 0.25" />
                            <joint damping="200" name="sjoint4" pos="0 0 -0.4" axis="0 1 0" limited="true" range="-3.14159 3.14159" />
                            <geom size="0.04 0.4" type="cylinder" rgba="0.5 0.5 0.8 1" />
                            <body name="spacecraft_link5" pos="-0.4 0 0.4" euler="0 -1.57 0">
                                <inertial pos="0 0 0" quat="0.5 0.5 0.5 0.5" mass="20" diaginertia="25 25 0.25" />
                                <joint damping="200" name="sjoint5" pos="0 0 -0.4" axis="1 0 0" limited="true" range="-3.14159 3.14159"/>
                                <geom size="0.04 0.4" type="cylinder" rgba="0.5 0 0.8 0.5" />
                                <body name="spacecraft_link6" pos="0 0 0.8" euler="0 0 0">
                                    <inertial pos="0 0 0" quat="0.5 0.5 0.5 0.5" mass="20" diaginertia="25 25 0.25" />
                                    <joint damping="200" name="sjoint6" pos="0 0 -0.4" axis="0 1 0" limited="true" range="-3.14159 3.14159" />
                                    <geom size="0.04 0.4" type="cylinder" rgba="0.5 0.5 0.5 1" />
                                    <body name="spacecraft_link7" pos="0 0 0.85" euler="0 0 0">
                                        <inertial pos="0 0 0" quat="0.5 0.5 0.5 0.5" mass="20" diaginertia="25 25re 0.25" />
                                        <joint damping="200" name="sjoint7" pos="0 0 0" axis="0 0 1" limited="true" range="-3.14159 3.14159" />
                                        <geom size="0.04 0.45" type="cylinder" rgba="0.2 0.3 0.4 0.5" />
                                        <geom pos="0 0 0.45" euler='0 0 -1.57' class="spaceRobot_viz" mesh="hand_viz"/>
                                        <geom pos="0 0 0.45" euler='0 0 -1.57' class="spaceRobot_col" mesh="hand_col" mass="0.81909"/>
                                        <site name='end_effector' pos='0 0 0.56' size='0.01' euler='0 0 -0.785398'/>

                                        <body name="leftfinger" pos="0 0 0.5154" euler='0 0 -1.57' childclass='spaceRobot_finger'>
                                            <inertial pos="-1.57863e-05 0.0118731 0.0434103" quat="0.705868 0.0310348 -0.0314925 0.706962" mass="0.0927059" diaginertia="6.57134e-05 6.09611e-05 1.09932e-05" />
<!--                                            <joint damping="200" name="finger_joint1"  axis="0 1 0" type="slide" range="0 0.04" class="spaceRobot_finger"/>-->

                                            <geom class="spaceRobot_viz" mesh="finger_viz"/>
                                            <!-- <geom class="spaceRobot_col" mesh="finger_col"/> -->
                                            <geom size="0.0070" fromto=".009 .006 .0875   -.009 .009 .0875" type="capsule" />
                                            <geom size="0.0070" fromto=".009 .009 .0875   -.009 .006 .0875" type="capsule" />

                                            <geom size="0.0075" fromto=".009 .007 .0775   -.009 .010 .0775" type="capsule" />
                                            <geom size="0.0075" fromto=".009 .010 .0775   -.009 .007 .0775" type="capsule" />

                                            <geom size="0.0082" fromto=".009 .008 .0675   -.009 .011 .0675" type="capsule" />
                                            <geom size="0.0082" fromto=".009 .011 .0675   -.009 .008 .0675" type="capsule" />

                                            <geom size="0.0090" fromto=".009 .009 .0575   -.009 .012 .0575" type="capsule" />
                                            <geom size="0.0090" fromto=".009 .012 .0575   -.009 .009 .0575" type="capsule" />

                                            <geom size="0.0100" fromto=".009 .0105 .0475   -.009 .0135 .0475" type="capsule" />
                                            <geom size="0.0100" fromto=".009 .0135 .0475   -.009 .0105 .0475" type="capsule" />

                                            <geom size="0.0110" fromto=".009 .012 .035   -.009 .015 .035" type="capsule" />
                                            <geom size="0.0110" fromto=".009 .015 .035   -.009 .012 .035" type="capsule" />

                                            <geom size="0.0185 0.0120 0.0175" pos="0 0.014 0.015" type="box" euler='.03 0 0' />
                                        </body>

                                        <body name="rightfinger" pos="0 0 0.5154" euler='0 0 -1.57'  childclass='spaceRobot_finger'>
                                            <inertial pos="1.57863e-05 -0.0118731 0.0434103" quat="0.705868 -0.0310348 0.0314925 0.706962" mass="0.0927059" diaginertia="6.57134e-05 6.09611e-05 1.09932e-05" />
<!--                                            <joint damping="200" name="finger_joint2" axis="0 -1 0" type="slide" range="0 0.04" class="spaceRobot_finger"/>-->
                                            <geom quat="0 0 0 1" class="spaceRobot_viz" mesh="finger_viz"/>
                                            <!-- <geom class="spaceRobot_col" mesh="finger_col"/> -->
                                            <geom size="0.0070" fromto=".009 -.006 .0875   -.009 -.009 .0875" type="capsule" />
                                            <geom size="0.0070" fromto=".009 -.009 .0875   -.009 -.006 .0875" type="capsule" />

                                            <geom size="0.0075" fromto=".009 -.007 .0775   -.009 -.010 .0775" type="capsule" />
                                            <geom size="0.0075" fromto=".009 -.010 .0775   -.009 -.007 .0775" type="capsule" />

                                            <geom size="0.0082" fromto=".009 -.008 .0675   -.009 -.011 .0675" type="capsule" />
                                            <geom size="0.0082" fromto=".009 -.011 .0675   -.009 -.008 .0675" type="capsule" />

                                            <geom size="0.0090" fromto=".009 -.009 .0575   -.009 -.012 .0575" type="capsule" />
                                            <geom size="0.0090" fromto=".009 -.012 .0575   -.009 -.009 .0575" type="capsule" />

                                            <geom size="0.0100" fromto=".009 -.0105 .0475   -.009 -.0135 .0475" type="capsule" />
                                            <geom size="0.0100" fromto=".009 -.0135 .0475   -.009 -.0105 .0475" type="capsule" />

                                            <geom size="0.0110" fromto=".009 -.012 .035   -.009 -.015 .035" type="capsule" />
                                            <geom size="0.0110" fromto=".009 -.015 .035   -.009 -.012 .035" type="capsule" />

                                            <geom size="0.0185 0.0120 0.0175" pos="0 -.014 0.015" type="box" euler='-.03 0 0' />
                                        </body>
                                    </body>
                                </body>
                            </body>
                        </body>
                    </body> 
                </body>
            </body>
        </body>
    </worldbody> 


    <!-- <actuator>
        <position name="motor1" joint="sjoint1" kp="870" forcerange="-87 87" ctrlrange="-2.9671 2.9671"/> 
        <position name="motor2" joint="sjoint2" kp="870" forcerange="-87 87" ctrlrange="-1.8326 1.8326"/> 
        <position name="motor3" joint="sjoint3" kp="870" forcerange="-87 87" ctrlrange="-2.9671 2.9671"/> 
        <position name="motor4" joint="sjoint4" kp="870" forcerange="-87 87" ctrlrange="-3.1416 0.0"/> 
        <position name="motor5" joint="sjoint5" kp="120" forcerange="-12 12" ctrlrange="-2.9671 2.9671"/>
        <position name="motor6" joint="sjoint6" kp="120" forcerange="-12 12" ctrlrange="-3.7525 2.1817"/> 
        <position name="motor7" joint="sjoint7" kp="120" forcerange="-12 12" ctrlrange="-2.9671 2.9671"/> 
        <position name="r_gripper_finger_joint" joint="finger_joint1" class="spaceRobot_finger" kp="500" forcerange="-70 70" ctrlrange="0 0.04"/>
        <position name="l_gripper_finger_joint" joint="finger_joint2" class="spaceRobot_finger" kp="500" forcerange="-70 70" ctrlrange="0 0.04"/>
    </actuator> -->

    <actuator>
        <motor name="motor1" joint="sjoint1" ctrlrange="-3 3" ctrllimited="true" />  <!-- gear='32' -->
        <motor name="motor2" joint="sjoint2" ctrlrange="-3 3" ctrllimited="true" />  <!-- gear='32' -->
        <motor name="motor3" joint="sjoint3" ctrlrange="-3 3" ctrllimited="true" />  <!-- gear='32' -->
        <motor name="motor4" joint="sjoint4" ctrlrange="-3 3" ctrllimited="true" />  <!-- gear='32' -->
        <motor name="motor5" joint="sjoint5" ctrlrange="-3 3" ctrllimited="true" />  <!-- gear='32' -->
        <motor name="motor6" joint="sjoint6" ctrlrange="-3 3" ctrllimited="true" />  <!-- gear='32' -->
        <motor name="motor7" joint="sjoint7" ctrlrange="-3 3" ctrllimited="true" />  <!-- gear='32' -->
<!--        <position name="r_grip_finger_joint" joint="finger_joint1" class="spaceRobot_finger" kp="500" forcerange="-70 70" ctrlrange="0 0.04"/>-->
<!--        <position name="l_grip_finger_joint" joint="finger_joint2" class="spaceRobot_finger" kp="500" forcerange="-70 70" ctrlrange="0 0.04"/>-->
    </actuator>

    <sensor>
        <gyro name="baseGyro" site="baseSite" noise="0.001" />
        <accelerometer name="baseAccel" site="baseSite" noise="0.001" />
        <jointpos name="encoderPos1" joint="sjoint1" noise="0.001" />
        <jointpos name="encoderPos2" joint="sjoint2" noise="0.001" /> 
        <jointpos name="encoderPos3" joint="sjoint3" noise="0.001" /> 
        <jointpos name="encoderPos4" joint="sjoint4" noise="0.001" />
        <jointpos name="encoderPos5" joint="sjoint5" noise="0.001" /> 
        <jointpos name="encoderPos6" joint="sjoint6" noise="0.001" /> 
        <jointpos name="encoderPos7" joint="sjoint7" noise="0.001" /> 
        
        <jointvel name="encoderVel1" joint="sjoint1" noise="0.001" />
        <jointvel name="encoderVel2" joint="sjoint2" noise="0.001" /> 
        <jointvel name="encoderVel3" joint="sjoint3" noise="0.001" /> 
        <jointvel name="encoderVel4" joint="sjoint4" noise="0.001" /> 
        <jointvel name="encoderVel5" joint="sjoint5" noise="0.001" /> 
        <jointvel name="encoderVel6" joint="sjoint6" noise="0.001" /> 
        <jointvel name="encoderVel7" joint="sjoint7" noise="0.001" /> 
    </sensor>

</mujoco>

